AgentsScraper:INFO - *****Point2Agent Bot Started*****
AgentsScraper:INFO - Agent links extracted: 0
AgentsScraper:INFO - Agent links extracted: 0
AgentsScraper:INFO - Agent links extracted: 0
AgentsScraperSQLHandler:INFO - Adding new agent to database
SQLHandler:INFO - Record added successfully
SQLHandler:INFO - Adding new agent to database
SQLHandler:INFO - Record added successfully
SQLHandler:INFO - Adding new agent to database
SQLHandler:INFO - Adding new agent to database
SQLHandler:INFO - Adding new agent to database
SQLHandler:INFO - Adding new agent to database
SQLHandler:INFO - Adding new agent to database
SQLHandler:INFO - Adding new agent to database
SQLHandler:INFO - Adding new agent to database
SQLHandler:INFO - Adding new agent to database
SQLHandler:INFO - Adding new agent to database
SQLHandler:INFO - Adding new agent to database
SQLHandler:INFO - Adding new agent to database
SQLHandler:INFO - Adding new agent to database
SQLHandler:INFO - Adding new agent to database
ent\env\Lib\site-packages\sqlalchemy\engine\default.py", line 921, in do_execute
    cursor.execute(statement, parameters)
sqlite3.IntegrityError: UNIQUE constraint failed: agents.agent_id

The above exception was the direct cause of the following exception:

Traceback (most recent call last):
  File "c:\Users\Towett\Desktop\point2agent\app\main.py", line 270, in __process_agent
    self.sql_handler.run(agent)
  File "c:\Users\Towett\Desktop\point2agent\utils\sql_handler.py", line 162, in run
    self.add_agent(agent)
  File "c:\Users\Towett\Desktop\point2agent\utils\sql_handler.py", line 72, in add_agent
    connection.execute(self.table.insert().values(
  File "C:\Users\Towett\Desktop\point2agent\env\Lib\site-packages\sqlalchemy\engine\base.py", line 1412, in execute
    return meth(
           ^^^^^
  File "C:\Users\Towett\Desktop\point2agent\env\Lib\site-packages\sqlalchemy\sql\elements.py", line 483, in _execute_on_connection
    return connection._execute_clauseelement(
           ^^^^^^^^^^^^^^^^^^^^^^^^^^^^^^^^^^
  File "C:\Users\Towett\Desktop\point2agent\env\Lib\site-packages\sqlalchemy\engine\base.py", line 1635, in _execute_clauseelement
    ret = self._execute_context(
          ^^^^^^^^^^^^^^^^^^^^^^
  File "C:\Users\Towett\Desktop\point2agent\env\Lib\site-packages\sqlalchemy\engine\base.py", line 1844, in _execute_context
    return self._exec_single_context(
           ^^^^^^^^^^^^^^^^^^^^^^^^^^
  File "C:\Users\Towett\Desktop\point2agent\env\Lib\site-packages\sqlalchemy\engine\base.py", line 1984, in _exec_single_context
    self._handle_dbapi_exception(
  File "C:\Users\Towett\Desktop\point2agent\env\Lib\site-packages\sqlalchemy\engine\base.py", line 2339, in _handle_dbapi_exception
    raise sqlalchemy_exception.with_traceback(exc_info[2]) from e
  File "C:\Users\Towett\Desktop\point2agent\env\Lib\site-packages\sqlalchemy\engine\base.py", line 1965, in _exec_single_context
    self.dialect.do_execute(
  File "C:\Users\Towett\Desktop\point2agent\env\Lib\site-packages\sqlalchemy\engine\default.py", line 921, in do_execute
    cursor.execute(statement, parameters)
sqlalchemy.exc.IntegrityError: (sqlite3.IntegrityError) UNIQUE constraint failed: agents.agent_id
[SQL: INSERT INTO agents (agent_id, name, location, agent_url, website, phone, office_phone, fax_phone, linkedin, facebook, description, date_scraped, contacted) VALUES (?, ?, ?, ?, ?, ?, ?, ?, ?, ?, ?, ?, ?)]
[parameters: ('2781524', 'Liszett Torres', '5th Avenue & 34th Street, Bosque de los Aluxes, Playa del Carmen, QR 77710', 'https://www.point2homes.com/MX/Real-Estate-Agents/Liszett-Torres/2781524.html', 'http://veronicasaucedo2.point2agent.com', '(198) 411-64666', None, None, None, 'https://www.facebook.com/SIRMEXICO', "RIVIERA MAYA SOTHEBY'S INTERNATIONAL REALTY", '2023-08-04 00:00:00.000000', 0)]
(Background on this error at: https://sqlalche.me/e/20/gkpj)
AgentsScraper:ERROR - 
Traceback (most recent call last):
  File "C:\Users\Towett\Desktop\point2agent\env\Lib\site-packages\sqlalchemy\engine\base.py", line 1965, in _exec_single_context
    self.dialect.do_execute(
  File "C:\Users\Towett\Desktop\point2agent\env\Lib\site-packages\sqlalchemy\engine\default.py", line 921, in do_execute
    cursor.execute(statement, parameters)
sqlite3.IntegrityError: UNIQUE constraint failed: agents.agent_id

The above exception was the direct cause of the following exception:

Traceback (most recent call last):
  File "c:\Users\Towett\Desktop\point2agent\app\main.py", line 270, in __process_agent
    self.sql_handler.run(agent)
  File "c:\Users\Towett\Desktop\point2agent\utils\sql_handler.py", line 162, in run
    self.add_agent(agent)
  File "c:\Users\Towett\Desktop\point2agent\utils\sql_handler.py", line 72, in add_agent
    connection.execute(self.table.insert().values(
  File "C:\Users\Towett\Desktop\point2agent\env\Lib\site-packages\sqlalchemy\engine\base.py", line 1412, in execute
    return meth(
           ^^^^^
  File "C:\Users\Towett\Desktop\point2agent\env\Lib\site-packages\sqlalchemy\sql\elements.py", line 483, in _execute_on_connection
    return connection._execute_clauseelement(
           ^^^^^^^^^^^^^^^^^^^^^^^^^^^^^^^^^^
  File "C:\Users\Towett\Desktop\point2agent\env\Lib\site-packages\sqlalchemy\engine\base.py", line 1635, in _execute_clauseelement
    ret = self._execute_context(
          ^^^^^^^^^^^^^^^^^^^^^^
  File "C:\Users\Towett\Desktop\point2agent\env\Lib\site-packages\sqlalchemy\engine\base.py", line 1844, in _execute_context
    return self._exec_single_context(
           ^^^^^^^^^^^^^^^^^^^^^^^^^^
  File "C:\Users\Towett\Desktop\point2agent\env\Lib\site-packages\sqlalchemy\engine\base.py", line 1984, in _exec_single_context
    self._handle_dbapi_exception(
  File "C:\Users\Towett\Desktop\point2agent\env\Lib\site-packages\sqlalchemy\engine\base.py", line 2339, in _handle_dbapi_exception
    raise sqlalchemy_exception.with_traceback(exc_info[2]) from e
  File "C:\Users\Towett\Desktop\point2agent\env\Lib\site-packages\sqlalchemy\engine\base.py", line 1965, in _exec_single_context
    self.dialect.do_execute(
  File "C:\Users\Towett\Desktop\point2agent\env\Lib\site-packages\sqlalchemy\engine\default.py", line 921, in do_execute
    cursor.execute(statement, parameters)
sqlalchemy.exc.IntegrityError: (sqlite3.IntegrityError) UNIQUE constraint failed: agents.agent_id
[SQL: INSERT INTO agents (agent_id, name, location, agent_url, website, phone, office_phone, fax_phone, linkedin, facebook, description, date_scraped, contacted) VALUES (?, ?, ?, ?, ?, ?, ?, ?, ?, ?, ?, ?, ?)]
[parameters: ('2781524', 'Liszett Torres', '5th Avenue & 34th Street, Bosque de los Aluxes, Playa del Carmen, QR 77710', 'https://www.point2homes.com/MX/Real-Estate-Agents/Liszett-Torres/2781524.html', 'http://veronicasaucedo2.point2agent.com', '(198) 411-64666', None, None, None, 'https://www.facebook.com/SIRMEXICO', "RIVIERA MAYA SOTHEBY'S INTERNATIONAL REALTY", '2023-08-04 00:00:00.000000', 0)]
(Background on this error at: https://sqlalche.me/e/20/gkpj)
AgentsScraper:ERROR - 
Traceback (most recent call last):
  File "C:\Users\Towett\Desktop\point2agent\env\Lib\site-packages\sqlalchemy\engine\base.py", line 1965, in _exec_single_context
    self.dialect.do_execute(
  File "C:\Users\Towett\Desktop\point2agent\env\Lib\site-packages\sqlalchemy\engine\default.py", line 921, in do_execute
    cursor.execute(statement, parameters)
sqlite3.IntegrityError: UNIQUE constraint failed: agents.agent_id

The above exception was the direct cause of the following exception:

Traceback (most recent call last):
  File "c:\Users\Towett\Desktop\point2agent\app\main.py", line 270, in __process_agent
    self.sql_handler.run(agent)
  File "c:\Users\Towett\Desktop\point2agent\utils\sql_handler.py", line 162, in run
    self.add_agent(agent)
  File "c:\Users\Towett\Desktop\point2agent\utils\sql_handler.py", line 72, in add_agent
    connection.execute(self.table.insert().values(
  File "C:\Users\Towett\Desktop\point2agent\env\Lib\site-packages\sqlalchemy\engine\base.py", line 1412, in execute
    return meth(
           ^^^^^
  File "C:\Users\Towett\Desktop\point2agent\env\Lib\site-packages\sqlalchemy\sql\elements.py", line 483, in _execute_on_connection
    return connection._execute_clauseelement(
           ^^^^^^^^^^^^^^^^^^^^^^^^^^^^^^^^^^
  File "C:\Users\Towett\Desktop\point2agent\env\Lib\site-packages\sqlalchemy\engine\base.py", line 1635, in _execute_clauseelement
    ret = self._execute_context(
          ^^^^^^^^^^^^^^^^^^^^^^
  File "C:\Users\Towett\Desktop\point2agent\env\Lib\site-packages\sqlalchemy\engine\base.py", line 1844, in _execute_context
    return self._exec_single_context(
           ^^^^^^^^^^^^^^^^^^^^^^^^^^
  File "C:\Users\Towett\Desktop\point2agent\env\Lib\site-packages\sqlalchemy\engine\base.py", line 1984, in _exec_single_context
    self._handle_dbapi_exception(
  File "C:\Users\Towett\Desktop\point2agent\env\Lib\site-packages\sqlalchemy\engine\base.py", line 2339, in _handle_dbapi_exception
    raise sqlalchemy_exception.with_traceback(exc_info[2]) from e
  File "C:\Users\Towett\Desktop\point2agent\env\Lib\site-packages\sqlalchemy\engine\base.py", line 1965, in _exec_single_context
    self.dialect.do_execute(
  File "C:\Users\Towett\Desktop\point2agent\env\Lib\site-packages\sqlalchemy\engine\default.py", line 921, in do_execute
    cursor.execute(statement, parameters)
sqlalchemy.exc.IntegrityError: (sqlite3.IntegrityError) UNIQUE constraint failed: agents.agent_id
[SQL: INSERT INTO agents (agent_id, name, location, agent_url, website, phone, office_phone, fax_phone, linkedin, facebook, description, date_scraped, contacted) VALUES (?, ?, ?, ?, ?, ?, ?, ?, ?, ?, ?, ?, ?)]
[parameters: ('4972316', 'Fernando Escamilla', 'GUARDIANES MAYAS, CENTRAL PARK LAGUNAS, LOCAL 1, Tulum, QR 77760', 'https://www.point2homes.com/MX/Real-Estate-Agents/Fernando-Escamilla/4972316.html', 'http://danielcortes.point2agent.com', None, '+52 (999) 258-7731', None, None, None, 'HIGHLINE MEXICO', '2023-08-04 00:00:00.000000', 0)]
(Background on this error at: https://sqlalche.me/e/20/gkpj)
AgentsScraper:ERROR - 
Traceback (most recent call last):
  File "C:\Users\Towett\Desktop\point2agent\env\Lib\site-packages\sqlalchemy\engine\base.py", line 1965, in _exec_single_context
    self.dialect.do_execute(
  File "C:\Users\Towett\Desktop\point2agent\env\Lib\site-packages\sqlalchemy\engine\default.py", line 921, in do_execute
    cursor.execute(statement, parameters)
sqlite3.IntegrityError: UNIQUE constraint failed: agents.agent_id

The above exception was the direct cause of the following exception:

Traceback (most recent call last):
  File "c:\Users\Towett\Desktop\point2agent\app\main.py", line 270, in __process_agent
    self.sql_handler.run(agent)
  File "c:\Users\Towett\Desktop\point2agent\utils\sql_handler.py", line 162, in run
    self.add_agent(agent)
  File "c:\Users\Towett\Desktop\point2agent\utils\sql_handler.py", line 72, in add_agent
    connection.execute(self.table.insert().values(
  File "C:\Users\Towett\Desktop\point2agent\env\Lib\site-packages\sqlalchemy\engine\base.py", line 1412, in execute
    return meth(
           ^^^^^
  File "C:\Users\Towett\Desktop\point2agent\env\Lib\site-packages\sqlalchemy\sql\elements.py", line 483, in _execute_on_connection
    return connection._execute_clauseelement(
           ^^^^^^^^^^^^^^^^^^^^^^^^^^^^^^^^^^
  File "C:\Users\Towett\Desktop\point2agent\env\Lib\site-packages\sqlalchemy\engine\base.py", line 1635, in _execute_clauseelement
    ret = self._execute_context(
          ^^^^^^^^^^^^^^^^^^^^^^
  File "C:\Users\Towett\Desktop\point2agent\env\Lib\site-packages\sqlalchemy\engine\base.py", line 1844, in _execute_context
    return self._exec_single_context(
           ^^^^^^^^^^^^^^^^^^^^^^^^^^
  File "C:\Users\Towett\Desktop\point2agent\env\Lib\site-packages\sqlalchemy\engine\base.py", line 1984, in _exec_single_context
    self._handle_dbapi_exception(
  File "C:\Users\Towett\Desktop\point2agent\env\Lib\site-packages\sqlalchemy\engine\base.py", line 2339, in _handle_dbapi_exception
    raise sqlalchemy_exception.with_traceback(exc_info[2]) from e
  File "C:\Users\Towett\Desktop\point2agent\env\Lib\site-packages\sqlalchemy\engine\base.py", line 1965, in _exec_single_context
    self.dialect.do_execute(
  File "C:\Users\Towett\Desktop\point2agent\env\Lib\site-packages\sqlalchemy\engine\default.py", line 921, in do_execute
    cursor.execute(statement, parameters)
sqlalchemy.exc.IntegrityError: (sqlite3.IntegrityError) UNIQUE constraint failed: agents.agent_id
[SQL: INSERT INTO agents (agent_id, name, location, agent_url, website, phone, office_phone, fax_phone, linkedin, facebook, description, date_scraped, contacted) VALUES (?, ?, ?, ?, ?, ?, ?, ?, ?, ?, ?, ?, ?)]
[parameters: ('2781524', 'Liszett Torres', '5th Avenue & 34th Street, Bosque de los Aluxes, Playa del Carmen, QR 77710', 'https://www.point2homes.com/MX/Real-Estate-Agents/Liszett-Torres/2781524.html', 'http://veronicasaucedo2.point2agent.com', '(198) 411-64666', None, None, None, 'https://www.facebook.com/SIRMEXICO', "RIVIERA MAYA SOTHEBY'S INTERNATIONAL REALTY", '2023-08-04 00:00:00.000000', 0)]
(Background on this error at: https://sqlalche.me/e/20/gkpj)
AgentsScraper:ERROR - 
Traceback (most recent call last):
  File "C:\Users\Towett\Desktop\point2agent\env\Lib\site-packages\sqlalchemy\engine\base.py", line 1965, in _exec_single_context
    self.dialect.do_execute(
  File "C:\Users\Towett\Desktop\point2agent\env\Lib\site-packages\sqlalchemy\engine\default.py", line 921, in do_execute
    cursor.execute(statement, parameters)
sqlite3.IntegrityError: UNIQUE constraint failed: agents.agent_id

The above exception was the direct cause of the following exception:

Traceback (most recent call last):
  File "c:\Users\Towett\Desktop\point2agent\app\main.py", line 270, in __process_agent
    self.sql_handler.run(agent)
  File "c:\Users\Towett\Desktop\point2agent\utils\sql_handler.py", line 162, in run
    self.add_agent(agent)
  File "c:\Users\Towett\Desktop\point2agent\utils\sql_handler.py", line 72, in add_agent
    connection.execute(self.table.insert().values(
  File "C:\Users\Towett\Desktop\point2agent\env\Lib\site-packages\sqlalchemy\engine\base.py", line 1412, in execute
    return meth(
           ^^^^^
  File "C:\Users\Towett\Desktop\point2agent\env\Lib\site-packages\sqlalchemy\sql\elements.py", line 483, in _execute_on_connection
    return connection._execute_clauseelement(
           ^^^^^^^^^^^^^^^^^^^^^^^^^^^^^^^^^^
  File "C:\Users\Towett\Desktop\point2agent\env\Lib\site-packages\sqlalchemy\engine\base.py", line 1635, in _execute_clauseelement
    ret = self._execute_context(
          ^^^^^^^^^^^^^^^^^^^^^^
  File "C:\Users\Towett\Desktop\point2agent\env\Lib\site-packages\sqlalchemy\engine\base.py", line 1844, in _execute_context
    return self._exec_single_context(
           ^^^^^^^^^^^^^^^^^^^^^^^^^^
  File "C:\Users\Towett\Desktop\point2agent\env\Lib\site-packages\sqlalchemy\engine\base.py", line 1984, in _exec_single_context
    self._handle_dbapi_exception(
  File "C:\Users\Towett\Desktop\point2agent\env\Lib\site-packages\sqlalchemy\engine\base.py", line 2339, in _handle_dbapi_exception
    raise sqlalchemy_exception.with_traceback(exc_info[2]) from e
  File "C:\Users\Towett\Desktop\point2agent\env\Lib\site-packages\sqlalchemy\engine\base.py", line 1965, in _exec_single_context
    self.dialect.do_execute(
  File "C:\Users\Towett\Desktop\point2agent\env\Lib\site-packages\sqlalchemy\engine\default.py", line 921, in do_execute
    cursor.execute(statement, parameters)
sqlalchemy.exc.IntegrityError: (sqlite3.IntegrityError) UNIQUE constraint failed: agents.agent_id
[SQL: INSERT INTO agents (agent_id, name, location, agent_url, website, phone, office_phone, fax_phone, linkedin, facebook, description, date_scraped, contacted) VALUES (?, ?, ?, ?, ?, ?, ?, ?, ?, ?, ?, ?, ?)]
[parameters: ('4972316', 'Fernando Escamilla', 'GUARDIANES MAYAS, CENTRAL PARK LAGUNAS, LOCAL 1, Tulum, QR 77760', 'https://www.point2homes.com/MX/Real-Estate-Agents/Fernando-Escamilla/4972316.html', 'http://danielcortes.point2agent.com', None, '+52 (999) 258-7731', None, None, None, 'HIGHLINE MEXICO', '2023-08-04 00:00:00.000000', 0)]
(Background on this error at: https://sqlalche.me/e/20/gkpj)
AgentsScraper:ERROR - 
Traceback (most recent call last):
  File "C:\Users\Towett\Desktop\point2agent\env\Lib\site-packages\sqlalchemy\engine\base.py", line 1965, in _exec_single_context
    self.dialect.do_execute(
  File "C:\Users\Towett\Desktop\point2agent\env\Lib\site-packages\sqlalchemy\engine\default.py", line 921, in do_execute
    cursor.execute(statement, parameters)
sqlite3.IntegrityError: UNIQUE constraint failed: agents.agent_id

The above exception was the direct cause of the following exception:

Traceback (most recent call last):
  File "c:\Users\Towett\Desktop\point2agent\app\main.py", line 270, in __process_agent
    self.sql_handler.run(agent)
  File "c:\Users\Towett\Desktop\point2agent\utils\sql_handler.py", line 162, in run
    self.add_agent(agent)
  File "c:\Users\Towett\Desktop\point2agent\utils\sql_handler.py", line 72, in add_agent
    connection.execute(self.table.insert().values(
  File "C:\Users\Towett\Desktop\point2agent\env\Lib\site-packages\sqlalchemy\engine\base.py", line 1412, in execute
    return meth(
           ^^^^^
  File "C:\Users\Towett\Desktop\point2agent\env\Lib\site-packages\sqlalchemy\sql\elements.py", line 483, in _execute_on_connection
    return connection._execute_clauseelement(
           ^^^^^^^^^^^^^^^^^^^^^^^^^^^^^^^^^^
  File "C:\Users\Towett\Desktop\point2agent\env\Lib\site-packages\sqlalchemy\engine\base.py", line 1635, in _execute_clauseelement
    ret = self._execute_context(
          ^^^^^^^^^^^^^^^^^^^^^^
  File "C:\Users\Towett\Desktop\point2agent\env\Lib\site-packages\sqlalchemy\engine\base.py", line 1844, in _execute_context
    return self._exec_single_context(
           ^^^^^^^^^^^^^^^^^^^^^^^^^^
  File "C:\Users\Towett\Desktop\point2agent\env\Lib\site-packages\sqlalchemy\engine\base.py", line 1984, in _exec_single_context
    self._handle_dbapi_exception(
  File "C:\Users\Towett\Desktop\point2agent\env\Lib\site-packages\sqlalchemy\engine\base.py", line 2339, in _handle_dbapi_exception
    raise sqlalchemy_exception.with_traceback(exc_info[2]) from e
  File "C:\Users\Towett\Desktop\point2agent\env\Lib\site-packages\sqlalchemy\engine\base.py", line 1965, in _exec_single_context
    self.dialect.do_execute(
  File "C:\Users\Towett\Desktop\point2agent\env\Lib\site-packages\sqlalchemy\engine\default.py", line 921, in do_execute
    cursor.execute(statement, parameters)
sqlalchemy.exc.IntegrityError: (sqlite3.IntegrityError) UNIQUE constraint failed: agents.agent_id
[SQL: INSERT INTO agents (agent_id, name, location, agent_url, website, phone, office_phone, fax_phone, linkedin, facebook, description, date_scraped, contacted) VALUES (?, ?, ?, ?, ?, ?, ?, ?, ?, ?, ?, ?, ?)]
[parameters: ('2781524', 'Liszett Torres', '5th Avenue & 34th Street, Bosque de los Aluxes, Playa del Carmen, QR 77710', 'https://www.point2homes.com/MX/Real-Estate-Agents/Liszett-Torres/2781524.html', 'http://veronicasaucedo2.point2agent.com', '(198) 411-64666', None, None, None, 'https://www.facebook.com/SIRMEXICO', "RIVIERA MAYA SOTHEBY'S INTERNATIONAL REALTY", '2023-08-04 00:00:00.000000', 0)]
(Background on this error at: https://sqlalche.me/e/20/gkpj)
AgentsScraper:ERROR - 
Traceback (most recent call last):
  File "C:\Users\Towett\Desktop\point2agent\env\Lib\site-packages\sqlalchemy\engine\base.py", line 1965, in _exec_single_context
    self.dialect.do_execute(
  File "C:\Users\Towett\Desktop\point2agent\env\Lib\site-packages\sqlalchemy\engine\default.py", line 921, in do_execute
    cursor.execute(statement, parameters)
sqlite3.IntegrityError: UNIQUE constraint failed: agents.agent_id

The above exception was the direct cause of the following exception:

Traceback (most recent call last):
  File "c:\Users\Towett\Desktop\point2agent\app\main.py", line 270, in __process_agent
    self.sql_handler.run(agent)
  File "c:\Users\Towett\Desktop\point2agent\utils\sql_handler.py", line 162, in run
    self.add_agent(agent)
  File "c:\Users\Towett\Desktop\point2agent\utils\sql_handler.py", line 72, in add_agent
    connection.execute(self.table.insert().values(
  File "C:\Users\Towett\Desktop\point2agent\env\Lib\site-packages\sqlalchemy\engine\base.py", line 1412, in execute
    return meth(
           ^^^^^
  File "C:\Users\Towett\Desktop\point2agent\env\Lib\site-packages\sqlalchemy\sql\elements.py", line 483, in _execute_on_connection
    return connection._execute_clauseelement(
           ^^^^^^^^^^^^^^^^^^^^^^^^^^^^^^^^^^
  File "C:\Users\Towett\Desktop\point2agent\env\Lib\site-packages\sqlalchemy\engine\base.py", line 1635, in _execute_clauseelement
    ret = self._execute_context(
          ^^^^^^^^^^^^^^^^^^^^^^
  File "C:\Users\Towett\Desktop\point2agent\env\Lib\site-packages\sqlalchemy\engine\base.py", line 1844, in _execute_context
    return self._exec_single_context(
           ^^^^^^^^^^^^^^^^^^^^^^^^^^
  File "C:\Users\Towett\Desktop\point2agent\env\Lib\site-packages\sqlalchemy\engine\base.py", line 1984, in _exec_single_context
    self._handle_dbapi_exception(
  File "C:\Users\Towett\Desktop\point2agent\env\Lib\site-packages\sqlalchemy\engine\base.py", line 2339, in _handle_dbapi_exception
    raise sqlalchemy_exception.with_traceback(exc_info[2]) from e
  File "C:\Users\Towett\Desktop\point2agent\env\Lib\site-packages\sqlalchemy\engine\base.py", line 1965, in _exec_single_context
    self.dialect.do_execute(
  File "C:\Users\Towett\Desktop\point2agent\env\Lib\site-packages\sqlalchemy\engine\default.py", line 921, in do_execute
    cursor.execute(statement, parameters)
sqlalchemy.exc.IntegrityError: (sqlite3.IntegrityError) UNIQUE constraint failed: agents.agent_id
[SQL: INSERT INTO agents (agent_id, name, location, agent_url, website, phone, office_phone, fax_phone, linkedin, facebook, description, date_scraped, contacted) VALUES (?, ?, ?, ?, ?, ?, ?, ?, ?, ?, ?, ?, ?)]
[parameters: ('4972316', 'Fernando Escamilla', 'GUARDIANES MAYAS, CENTRAL PARK LAGUNAS, LOCAL 1, Tulum, QR 77760', 'https://www.point2homes.com/MX/Real-Estate-Agents/Fernando-Escamilla/4972316.html', 'http://danielcortes.point2agent.com', None, '+52 (999) 258-7731', None, None, None, 'HIGHLINE MEXICO', '2023-08-04 00:00:00.000000', 0)]
(Background on this error at: https://sqlalche.me/e/20/gkpj)
AgentsScraper:ERROR - 
Traceback (most recent call last):
  File "C:\Users\Towett\Desktop\point2agent\env\Lib\site-packages\sqlalchemy\engine\base.py", line 1965, in _exec_single_context
    self.dialect.do_execute(
  File "C:\Users\Towett\Desktop\point2agent\env\Lib\site-packages\sqlalchemy\engine\default.py", line 921, in do_execute
    cursor.execute(statement, parameters)
sqlite3.IntegrityError: UNIQUE constraint failed: agents.agent_id

The above exception was the direct cause of the following exception:

Traceback (most recent call last):
  File "c:\Users\Towett\Desktop\point2agent\app\main.py", line 270, in __process_agent
    self.sql_handler.run(agent)
  File "c:\Users\Towett\Desktop\point2agent\utils\sql_handler.py", line 162, in run
    self.add_agent(agent)
  File "c:\Users\Towett\Desktop\point2agent\utils\sql_handler.py", line 72, in add_agent
    connection.execute(self.table.insert().values(
  File "C:\Users\Towett\Desktop\point2agent\env\Lib\site-packages\sqlalchemy\engine\base.py", line 1412, in execute
    return meth(
           ^^^^^
  File "C:\Users\Towett\Desktop\point2agent\env\Lib\site-packages\sqlalchemy\sql\elements.py", line 483, in _execute_on_connection
    return connection._execute_clauseelement(
           ^^^^^^^^^^^^^^^^^^^^^^^^^^^^^^^^^^
  File "C:\Users\Towett\Desktop\point2agent\env\Lib\site-packages\sqlalchemy\engine\base.py", line 1635, in _execute_clauseelement
    ret = self._execute_context(
          ^^^^^^^^^^^^^^^^^^^^^^
  File "C:\Users\Towett\Desktop\point2agent\env\Lib\site-packages\sqlalchemy\engine\base.py", line 1844, in _execute_context
    return self._exec_single_context(
           ^^^^^^^^^^^^^^^^^^^^^^^^^^
  File "C:\Users\Towett\Desktop\point2agent\env\Lib\site-packages\sqlalchemy\engine\base.py", line 1984, in _exec_single_context
    self._handle_dbapi_exception(
  File "C:\Users\Towett\Desktop\point2agent\env\Lib\site-packages\sqlalchemy\engine\base.py", line 2339, in _handle_dbapi_exception
    raise sqlalchemy_exception.with_traceback(exc_info[2]) from e
  File "C:\Users\Towett\Desktop\point2agent\env\Lib\site-packages\sqlalchemy\engine\base.py", line 1965, in _exec_single_context
    self.dialect.do_execute(
  File "C:\Users\Towett\Desktop\point2agent\env\Lib\site-packages\sqlalchemy\engine\default.py", line 921, in do_execute
    cursor.execute(statement, parameters)
sqlalchemy.exc.IntegrityError: (sqlite3.IntegrityError) UNIQUE constraint failed: agents.agent_id
[SQL: INSERT INTO agents (agent_id, name, location, agent_url, website, phone, office_phone, fax_phone, linkedin, facebook, description, date_scraped, contacted) VALUES (?, ?, ?, ?, ?, ?, ?, ?, ?, ?, ?, ?, ?)]
[parameters: ('4972316', 'Fernando Escamilla', 'GUARDIANES MAYAS, CENTRAL PARK LAGUNAS, LOCAL 1, Tulum, QR 77760', 'https://www.point2homes.com/MX/Real-Estate-Agents/Fernando-Escamilla/4972316.html', 'http://danielcortes.point2agent.com', None, '+52 (999) 258-7731', None, None, None, 'HIGHLINE MEXICO', '2023-08-04 00:00:00.000000', 0)]
(Background on this error at: https://sqlalche.me/e/20/gkpj)
AgentsScraper:ERROR - 
Traceback (most recent call last):
  File "C:\Users\Towett\Desktop\point2agent\env\Lib\site-packages\sqlalchemy\engine\base.py", line 1965, in _exec_single_context
    self.dialect.do_execute(
  File "C:\Users\Towett\Desktop\point2agent\env\Lib\site-packages\sqlalchemy\engine\default.py", line 921, in do_execute
    cursor.execute(statement, parameters)
sqlite3.IntegrityError: UNIQUE constraint failed: agents.agent_id

The above exception was the direct cause of the following exception:

Traceback (most recent call last):
  File "c:\Users\Towett\Desktop\point2agent\app\main.py", line 270, in __process_agent
    self.sql_handler.run(agent)
  File "c:\Users\Towett\Desktop\point2agent\utils\sql_handler.py", line 162, in run
    self.add_agent(agent)
  File "c:\Users\Towett\Desktop\point2agent\utils\sql_handler.py", line 72, in add_agent
    connection.execute(self.table.insert().values(
  File "C:\Users\Towett\Desktop\point2agent\env\Lib\site-packages\sqlalchemy\engine\base.py", line 1412, in execute
    return meth(
           ^^^^^
  File "C:\Users\Towett\Desktop\point2agent\env\Lib\site-packages\sqlalchemy\sql\elements.py", line 483, in _execute_on_connection
    return connection._execute_clauseelement(
           ^^^^^^^^^^^^^^^^^^^^^^^^^^^^^^^^^^
  File "C:\Users\Towett\Desktop\point2agent\env\Lib\site-packages\sqlalchemy\engine\base.py", line 1635, in _execute_clauseelement
    ret = self._execute_context(
          ^^^^^^^^^^^^^^^^^^^^^^
  File "C:\Users\Towett\Desktop\point2agent\env\Lib\site-packages\sqlalchemy\engine\base.py", line 1844, in _execute_context
    return self._exec_single_context(
           ^^^^^^^^^^^^^^^^^^^^^^^^^^
  File "C:\Users\Towett\Desktop\point2agent\env\Lib\site-packages\sqlalchemy\engine\base.py", line 1984, in _exec_single_context
    self._handle_dbapi_exception(
  File "C:\Users\Towett\Desktop\point2agent\env\Lib\site-packages\sqlalchemy\engine\base.py", line 2339, in _handle_dbapi_exception
    raise sqlalchemy_exception.with_traceback(exc_info[2]) from e
  File "C:\Users\Towett\Desktop\point2agent\env\Lib\site-packages\sqlalchemy\engine\base.py", line 1965, in _exec_single_context
    self.dialect.do_execute(
  File "C:\Users\Towett\Desktop\point2agent\env\Lib\site-packages\sqlalchemy\engine\default.py", line 921, in do_execute
    cursor.execute(statement, parameters)
sqlalchemy.exc.IntegrityError: (sqlite3.IntegrityError) UNIQUE constraint failed: agents.agent_id
[SQL: INSERT INTO agents (agent_id, name, location, agent_url, website, phone, office_phone, fax_phone, linkedin, facebook, description, date_scraped, contacted) VALUES (?, ?, ?, ?, ?, ?, ?, ?, ?, ?, ?, ?, ?)]
[parameters: ('2781524', 'Liszett Torres', '5th Avenue & 34th Street, Bosque de los Aluxes, Playa del Carmen, QR 77710', 'https://www.point2homes.com/MX/Real-Estate-Agents/Liszett-Torres/2781524.html', 'http://veronicasaucedo2.point2agent.com', '(198) 411-64666', None, None, None, 'https://www.facebook.com/SIRMEXICO', "RIVIERA MAYA SOTHEBY'S INTERNATIONAL REALTY", '2023-08-04 00:00:00.000000', 0)]
(Background on this error at: https://sqlalche.me/e/20/gkpj)
AgentsScraper:ERROR - 
Traceback (most recent call last):
  File "C:\Users\Towett\Desktop\point2agent\env\Lib\site-packages\sqlalchemy\engine\base.py", line 1965, in _exec_single_context
    self.dialect.do_execute(
  File "C:\Users\Towett\Desktop\point2agent\env\Lib\site-packages\sqlalchemy\engine\default.py", line 921, in do_execute
    cursor.execute(statement, parameters)
sqlite3.IntegrityError: UNIQUE constraint failed: agents.agent_id

The above exception was the direct cause of the following exception:

Traceback (most recent call last):
  File "c:\Users\Towett\Desktop\point2agent\app\main.py", line 270, in __process_agent
    self.sql_handler.run(agent)
  File "c:\Users\Towett\Desktop\point2agent\utils\sql_handler.py", line 162, in run
    self.add_agent(agent)
  File "c:\Users\Towett\Desktop\point2agent\utils\sql_handler.py", line 72, in add_agent
    connection.execute(self.table.insert().values(
  File "C:\Users\Towett\Desktop\point2agent\env\Lib\site-packages\sqlalchemy\engine\base.py", line 1412, in execute
    return meth(
           ^^^^^
  File "C:\Users\Towett\Desktop\point2agent\env\Lib\site-packages\sqlalchemy\sql\elements.py", line 483, in _execute_on_connection
    return connection._execute_clauseelement(
           ^^^^^^^^^^^^^^^^^^^^^^^^^^^^^^^^^^
  File "C:\Users\Towett\Desktop\point2agent\env\Lib\site-packages\sqlalchemy\engine\base.py", line 1635, in _execute_clauseelement
    ret = self._execute_context(
          ^^^^^^^^^^^^^^^^^^^^^^
  File "C:\Users\Towett\Desktop\point2agent\env\Lib\site-packages\sqlalchemy\engine\base.py", line 1844, in _execute_context
    return self._exec_single_context(
           ^^^^^^^^^^^^^^^^^^^^^^^^^^
  File "C:\Users\Towett\Desktop\point2agent\env\Lib\site-packages\sqlalchemy\engine\base.py", line 1984, in _exec_single_context
    self._handle_dbapi_exception(
  File "C:\Users\Towett\Desktop\point2agent\env\Lib\site-packages\sqlalchemy\engine\base.py", line 2339, in _handle_dbapi_exception
    raise sqlalchemy_exception.with_traceback(exc_info[2]) from e
  File "C:\Users\Towett\Desktop\point2agent\env\Lib\site-packages\sqlalchemy\engine\base.py", line 1965, in _exec_single_context
    self.dialect.do_execute(
  File "C:\Users\Towett\Desktop\point2agent\env\Lib\site-packages\sqlalchemy\engine\default.py", line 921, in do_execute
    cursor.execute(statement, parameters)
sqlalchemy.exc.IntegrityError: (sqlite3.IntegrityError) UNIQUE constraint failed: agents.agent_id
[SQL: INSERT INTO agents (agent_id, name, location, agent_url, website, phone, office_phone, fax_phone, linkedin, facebook, description, date_scraped, contacted) VALUES (?, ?, ?, ?, ?, ?, ?, ?, ?, ?, ?, ?, ?)]
[parameters: ('4972316', 'Fernando Escamilla', 'GUARDIANES MAYAS, CENTRAL PARK LAGUNAS, LOCAL 1, Tulum, QR 77760', 'https://www.point2homes.com/MX/Real-Estate-Agents/Fernando-Escamilla/4972316.html', 'http://danielcortes.point2agent.com', None, '+52 (999) 258-7731', None, None, None, 'HIGHLINE MEXICO', '2023-08-04 00:00:00.000000', 0)]
(Background on this error at: https://sqlalche.me/e/20/gkpj)
AgentsScraper:ERROR - 
Traceback (most recent call last):
  File "C:\Users\Towett\Desktop\point2agent\env\Lib\site-packages\sqlalchemy\engine\base.py", line 1965, in _exec_single_context
    self.dialect.do_execute(
  File "C:\Users\Towett\Desktop\point2agent\env\Lib\site-packages\sqlalchemy\engine\default.py", line 921, in do_execute
    cursor.execute(statement, parameters)
sqlite3.IntegrityError: UNIQUE constraint failed: agents.agent_id

The above exception was the direct cause of the following exception:

Traceback (most recent call last):
  File "c:\Users\Towett\Desktop\point2agent\app\main.py", line 270, in __process_agent
    self.sql_handler.run(agent)
  File "c:\Users\Towett\Desktop\point2agent\utils\sql_handler.py", line 162, in run
    self.add_agent(agent)
  File "c:\Users\Towett\Desktop\point2agent\utils\sql_handler.py", line 72, in add_agent
    connection.execute(self.table.insert().values(
  File "C:\Users\Towett\Desktop\point2agent\env\Lib\site-packages\sqlalchemy\engine\base.py", line 1412, in execute
    return meth(
           ^^^^^
  File "C:\Users\Towett\Desktop\point2agent\env\Lib\site-packages\sqlalchemy\sql\elements.py", line 483, in _execute_on_connection
    return connection._execute_clauseelement(
           ^^^^^^^^^^^^^^^^^^^^^^^^^^^^^^^^^^
  File "C:\Users\Towett\Desktop\point2agent\env\Lib\site-packages\sqlalchemy\engine\base.py", line 1635, in _execute_clauseelement
    ret = self._execute_context(
          ^^^^^^^^^^^^^^^^^^^^^^
  File "C:\Users\Towett\Desktop\point2agent\env\Lib\site-packages\sqlalchemy\engine\base.py", line 1844, in _execute_context
    return self._exec_single_context(
           ^^^^^^^^^^^^^^^^^^^^^^^^^^
  File "C:\Users\Towett\Desktop\point2agent\env\Lib\site-packages\sqlalchemy\engine\base.py", line 1984, in _exec_single_context
    self._handle_dbapi_exception(
  File "C:\Users\Towett\Desktop\point2agent\env\Lib\site-packages\sqlalchemy\engine\base.py", line 2339, in _handle_dbapi_exception
    raise sqlalchemy_exception.with_traceback(exc_info[2]) from e
  File "C:\Users\Towett\Desktop\point2agent\env\Lib\site-packages\sqlalchemy\engine\base.py", line 1965, in _exec_single_context
    self.dialect.do_execute(
  File "C:\Users\Towett\Desktop\point2agent\env\Lib\site-packages\sqlalchemy\engine\default.py", line 921, in do_execute
    cursor.execute(statement, parameters)
sqlalchemy.exc.IntegrityError: (sqlite3.IntegrityError) UNIQUE constraint failed: agents.agent_id
[SQL: INSERT INTO agents (agent_id, name, location, agent_url, website, phone, office_phone, fax_phone, linkedin, facebook, description, date_scraped, contacted) VALUES (?, ?, ?, ?, ?, ?, ?, ?, ?, ?, ?, ?, ?)]
[parameters: ('2781524', 'Liszett Torres', '5th Avenue & 34th Street, Bosque de los Aluxes, Playa del Carmen, QR 77710', 'https://www.point2homes.com/MX/Real-Estate-Agents/Liszett-Torres/2781524.html', 'http://veronicasaucedo2.point2agent.com', '(198) 411-64666', None, None, None, 'https://www.facebook.com/SIRMEXICO', "RIVIERA MAYA SOTHEBY'S INTERNATIONAL REALTY", '2023-08-04 00:00:00.000000', 0)]
(Background on this error at: https://sqlalche.me/e/20/gkpj)
AgentsScraper:ERROR - 
Traceback (most recent call last):
  File "C:\Users\Towett\Desktop\point2agent\env\Lib\site-packages\sqlalchemy\engine\base.py", line 1965, in _exec_single_context
    self.dialect.do_execute(
  File "C:\Users\Towett\Desktop\point2agent\env\Lib\site-packages\sqlalchemy\engine\default.py", line 921, in do_execute
    cursor.execute(statement, parameters)
sqlite3.IntegrityError: UNIQUE constraint failed: agents.agent_id

The above exception was the direct cause of the following exception:

Traceback (most recent call last):
  File "c:\Users\Towett\Desktop\point2agent\app\main.py", line 270, in __process_agent
    self.sql_handler.run(agent)
  File "c:\Users\Towett\Desktop\point2agent\utils\sql_handler.py", line 162, in run
    self.add_agent(agent)
  File "c:\Users\Towett\Desktop\point2agent\utils\sql_handler.py", line 72, in add_agent
    connection.execute(self.table.insert().values(
  File "C:\Users\Towett\Desktop\point2agent\env\Lib\site-packages\sqlalchemy\engine\base.py", line 1412, in execute
    return meth(
           ^^^^^
  File "C:\Users\Towett\Desktop\point2agent\env\Lib\site-packages\sqlalchemy\sql\elements.py", line 483, in _execute_on_connection
    return connection._execute_clauseelement(
           ^^^^^^^^^^^^^^^^^^^^^^^^^^^^^^^^^^
  File "C:\Users\Towett\Desktop\point2agent\env\Lib\site-packages\sqlalchemy\engine\base.py", line 1635, in _execute_clauseelement
    ret = self._execute_context(
          ^^^^^^^^^^^^^^^^^^^^^^
  File "C:\Users\Towett\Desktop\point2agent\env\Lib\site-packages\sqlalchemy\engine\base.py", line 1844, in _execute_context
    return self._exec_single_context(
           ^^^^^^^^^^^^^^^^^^^^^^^^^^
  File "C:\Users\Towett\Desktop\point2agent\env\Lib\site-packages\sqlalchemy\engine\base.py", line 1984, in _exec_single_context
    self._handle_dbapi_exception(
  File "C:\Users\Towett\Desktop\point2agent\env\Lib\site-packages\sqlalchemy\engine\base.py", line 2339, in _handle_dbapi_exception
    raise sqlalchemy_exception.with_traceback(exc_info[2]) from e
  File "C:\Users\Towett\Desktop\point2agent\env\Lib\site-packages\sqlalchemy\engine\base.py", line 1965, in _exec_single_context
    self.dialect.do_execute(
  File "C:\Users\Towett\Desktop\point2agent\env\Lib\site-packages\sqlalchemy\engine\default.py", line 921, in do_execute
    cursor.execute(statement, parameters)
sqlalchemy.exc.IntegrityError: (sqlite3.IntegrityError) UNIQUE constraint failed: agents.agent_id
[SQL: INSERT INTO agents (agent_id, name, location, agent_url, website, phone, office_phone, fax_phone, linkedin, facebook, description, date_scraped, contacted) VALUES (?, ?, ?, ?, ?, ?, ?, ?, ?, ?, ?, ?, ?)]
[parameters: ('4972316', 'Fernando Escamilla', 'GUARDIANES MAYAS, CENTRAL PARK LAGUNAS, LOCAL 1, Tulum, QR 77760', 'https://www.point2homes.com/MX/Real-Estate-Agents/Fernando-Escamilla/4972316.html', 'http://danielcortes.point2agent.com', None, '+52 (999) 258-7731', None, None, None, 'HIGHLINE MEXICO', '2023-08-04 00:00:00.000000', 0)]
(Background on this error at: https://sqlalche.me/e/20/gkpj)
AgentsScraper:ERROR - 
Traceback (most recent call last):
  File "C:\Users\Towett\Desktop\point2agent\env\Lib\site-packages\sqlalchemy\engine\base.py", line 1965, in _exec_single_context
    self.dialect.do_execute(
  File "C:\Users\Towett\Desktop\point2agent\env\Lib\site-packages\sqlalchemy\engine\default.py", line 921, in do_execute
    cursor.execute(statement, parameters)
sqlite3.IntegrityError: UNIQUE constraint failed: agents.agent_id

The above exception was the direct cause of the following exception:

Traceback (most recent call last):
  File "c:\Users\Towett\Desktop\point2agent\app\main.py", line 270, in __process_agent
    self.sql_handler.run(agent)
  File "c:\Users\Towett\Desktop\point2agent\utils\sql_handler.py", line 162, in run
    self.add_agent(agent)
  File "c:\Users\Towett\Desktop\point2agent\utils\sql_handler.py", line 72, in add_agent
    connection.execute(self.table.insert().values(
  File "C:\Users\Towett\Desktop\point2agent\env\Lib\site-packages\sqlalchemy\engine\base.py", line 1412, in execute
    return meth(
           ^^^^^
  File "C:\Users\Towett\Desktop\point2agent\env\Lib\site-packages\sqlalchemy\sql\elements.py", line 483, in _execute_on_connection
    return connection._execute_clauseelement(
           ^^^^^^^^^^^^^^^^^^^^^^^^^^^^^^^^^^
  File "C:\Users\Towett\Desktop\point2agent\env\Lib\site-packages\sqlalchemy\engine\base.py", line 1635, in _execute_clauseelement
    ret = self._execute_context(
          ^^^^^^^^^^^^^^^^^^^^^^
  File "C:\Users\Towett\Desktop\point2agent\env\Lib\site-packages\sqlalchemy\engine\base.py", line 1844, in _execute_context
    return self._exec_single_context(
           ^^^^^^^^^^^^^^^^^^^^^^^^^^
  File "C:\Users\Towett\Desktop\point2agent\env\Lib\site-packages\sqlalchemy\engine\base.py", line 1984, in _exec_single_context
    self._handle_dbapi_exception(
  File "C:\Users\Towett\Desktop\point2agent\env\Lib\site-packages\sqlalchemy\engine\base.py", line 2339, in _handle_dbapi_exception
    raise sqlalchemy_exception.with_traceback(exc_info[2]) from e
  File "C:\Users\Towett\Desktop\point2agent\env\Lib\site-packages\sqlalchemy\engine\base.py", line 1965, in _exec_single_context
    self.dialect.do_execute(
  File "C:\Users\Towett\Desktop\point2agent\env\Lib\site-packages\sqlalchemy\engine\default.py", line 921, in do_execute
    cursor.execute(statement, parameters)
sqlalchemy.exc.IntegrityError: (sqlite3.IntegrityError) UNIQUE constraint failed: agents.agent_id
[SQL: INSERT INTO agents (agent_id, name, location, agent_url, website, phone, office_phone, fax_phone, linkedin, facebook, description, date_scraped, contacted) VALUES (?, ?, ?, ?, ?, ?, ?, ?, ?, ?, ?, ?, ?)]
[parameters: ('2781524', 'Liszett Torres', '5th Avenue & 34th Street, Bosque de los Aluxes, Playa del Carmen, QR 77710', 'https://www.point2homes.com/MX/Real-Estate-Agents/Liszett-Torres/2781524.html', 'http://veronicasaucedo2.point2agent.com', '(198) 411-64666', None, None, None, 'https://www.facebook.com/SIRMEXICO', "RIVIERA MAYA SOTHEBY'S INTERNATIONAL REALTY", '2023-08-04 00:00:00.000000', 0)]
(Background on this error at: https://sqlalche.me/e/20/gkpj)
